2019-09-11 17:54:12,931 INFO: Microblog startup [in /home/m0nte-cr1st0/flask_projects/grinberg_blog/app/__init__.py:44]
2019-09-11 17:55:08,725 INFO: Microblog startup [in /home/m0nte-cr1st0/flask_projects/grinberg_blog/app/__init__.py:44]
2019-09-11 17:56:18,860 INFO: Microblog startup [in /home/m0nte-cr1st0/flask_projects/grinberg_blog/app/__init__.py:46]
2019-09-11 17:58:18,144 INFO: Microblog startup [in /home/m0nte-cr1st0/flask_projects/grinberg_blog/app/__init__.py:46]
2019-09-11 18:00:59,528 ERROR: Exception on /edit_profile [POST] [in /home/m0nte-cr1st0/.virtualenvs/grinberg_blog/lib/python3.6/site-packages/flask/app.py:1891]
Traceback (most recent call last):
  File "/home/m0nte-cr1st0/.virtualenvs/grinberg_blog/lib/python3.6/site-packages/sqlalchemy/engine/base.py", line 1249, in _execute_context
    cursor, statement, parameters, context
  File "/home/m0nte-cr1st0/.virtualenvs/grinberg_blog/lib/python3.6/site-packages/sqlalchemy/engine/default.py", line 552, in do_execute
    cursor.execute(statement, parameters)
sqlite3.IntegrityError: UNIQUE constraint failed: user.username

The above exception was the direct cause of the following exception:

Traceback (most recent call last):
  File "/home/m0nte-cr1st0/.virtualenvs/grinberg_blog/lib/python3.6/site-packages/flask/app.py", line 2446, in wsgi_app
    response = self.full_dispatch_request()
  File "/home/m0nte-cr1st0/.virtualenvs/grinberg_blog/lib/python3.6/site-packages/flask/app.py", line 1951, in full_dispatch_request
    rv = self.handle_user_exception(e)
  File "/home/m0nte-cr1st0/.virtualenvs/grinberg_blog/lib/python3.6/site-packages/flask/app.py", line 1820, in handle_user_exception
    reraise(exc_type, exc_value, tb)
  File "/home/m0nte-cr1st0/.virtualenvs/grinberg_blog/lib/python3.6/site-packages/flask/_compat.py", line 39, in reraise
    raise value
  File "/home/m0nte-cr1st0/.virtualenvs/grinberg_blog/lib/python3.6/site-packages/flask/app.py", line 1949, in full_dispatch_request
    rv = self.dispatch_request()
  File "/home/m0nte-cr1st0/.virtualenvs/grinberg_blog/lib/python3.6/site-packages/flask/app.py", line 1935, in dispatch_request
    return self.view_functions[rule.endpoint](**req.view_args)
  File "/home/m0nte-cr1st0/.virtualenvs/grinberg_blog/lib/python3.6/site-packages/flask_login/utils.py", line 261, in decorated_view
    return func(*args, **kwargs)
  File "/home/m0nte-cr1st0/flask_projects/grinberg_blog/app/routes.py", line 99, in edit_profile
    db.session.commit()
  File "/home/m0nte-cr1st0/.virtualenvs/grinberg_blog/lib/python3.6/site-packages/sqlalchemy/orm/scoping.py", line 162, in do
    return getattr(self.registry(), name)(*args, **kwargs)
  File "/home/m0nte-cr1st0/.virtualenvs/grinberg_blog/lib/python3.6/site-packages/sqlalchemy/orm/session.py", line 1027, in commit
    self.transaction.commit()
  File "/home/m0nte-cr1st0/.virtualenvs/grinberg_blog/lib/python3.6/site-packages/sqlalchemy/orm/session.py", line 494, in commit
    self._prepare_impl()
  File "/home/m0nte-cr1st0/.virtualenvs/grinberg_blog/lib/python3.6/site-packages/sqlalchemy/orm/session.py", line 473, in _prepare_impl
    self.session.flush()
  File "/home/m0nte-cr1st0/.virtualenvs/grinberg_blog/lib/python3.6/site-packages/sqlalchemy/orm/session.py", line 2459, in flush
    self._flush(objects)
  File "/home/m0nte-cr1st0/.virtualenvs/grinberg_blog/lib/python3.6/site-packages/sqlalchemy/orm/session.py", line 2597, in _flush
    transaction.rollback(_capture_exception=True)
  File "/home/m0nte-cr1st0/.virtualenvs/grinberg_blog/lib/python3.6/site-packages/sqlalchemy/util/langhelpers.py", line 68, in __exit__
    compat.reraise(exc_type, exc_value, exc_tb)
  File "/home/m0nte-cr1st0/.virtualenvs/grinberg_blog/lib/python3.6/site-packages/sqlalchemy/util/compat.py", line 153, in reraise
    raise value
  File "/home/m0nte-cr1st0/.virtualenvs/grinberg_blog/lib/python3.6/site-packages/sqlalchemy/orm/session.py", line 2557, in _flush
    flush_context.execute()
  File "/home/m0nte-cr1st0/.virtualenvs/grinberg_blog/lib/python3.6/site-packages/sqlalchemy/orm/unitofwork.py", line 422, in execute
    rec.execute(self)
  File "/home/m0nte-cr1st0/.virtualenvs/grinberg_blog/lib/python3.6/site-packages/sqlalchemy/orm/unitofwork.py", line 589, in execute
    uow,
  File "/home/m0nte-cr1st0/.virtualenvs/grinberg_blog/lib/python3.6/site-packages/sqlalchemy/orm/persistence.py", line 236, in save_obj
    update,
  File "/home/m0nte-cr1st0/.virtualenvs/grinberg_blog/lib/python3.6/site-packages/sqlalchemy/orm/persistence.py", line 996, in _emit_update_statements
    statement, multiparams
  File "/home/m0nte-cr1st0/.virtualenvs/grinberg_blog/lib/python3.6/site-packages/sqlalchemy/engine/base.py", line 988, in execute
    return meth(self, multiparams, params)
  File "/home/m0nte-cr1st0/.virtualenvs/grinberg_blog/lib/python3.6/site-packages/sqlalchemy/sql/elements.py", line 287, in _execute_on_connection
    return connection._execute_clauseelement(self, multiparams, params)
  File "/home/m0nte-cr1st0/.virtualenvs/grinberg_blog/lib/python3.6/site-packages/sqlalchemy/engine/base.py", line 1107, in _execute_clauseelement
    distilled_params,
  File "/home/m0nte-cr1st0/.virtualenvs/grinberg_blog/lib/python3.6/site-packages/sqlalchemy/engine/base.py", line 1253, in _execute_context
    e, statement, parameters, cursor, context
  File "/home/m0nte-cr1st0/.virtualenvs/grinberg_blog/lib/python3.6/site-packages/sqlalchemy/engine/base.py", line 1473, in _handle_dbapi_exception
    util.raise_from_cause(sqlalchemy_exception, exc_info)
  File "/home/m0nte-cr1st0/.virtualenvs/grinberg_blog/lib/python3.6/site-packages/sqlalchemy/util/compat.py", line 398, in raise_from_cause
    reraise(type(exception), exception, tb=exc_tb, cause=cause)
  File "/home/m0nte-cr1st0/.virtualenvs/grinberg_blog/lib/python3.6/site-packages/sqlalchemy/util/compat.py", line 152, in reraise
    raise value.with_traceback(tb)
  File "/home/m0nte-cr1st0/.virtualenvs/grinberg_blog/lib/python3.6/site-packages/sqlalchemy/engine/base.py", line 1249, in _execute_context
    cursor, statement, parameters, context
  File "/home/m0nte-cr1st0/.virtualenvs/grinberg_blog/lib/python3.6/site-packages/sqlalchemy/engine/default.py", line 552, in do_execute
    cursor.execute(statement, parameters)
sqlalchemy.exc.IntegrityError: (sqlite3.IntegrityError) UNIQUE constraint failed: user.username
[SQL: UPDATE user SET username=?, about_me=? WHERE user.id = ?]
[parameters: ('admin', '', 2)]
(Background on this error at: http://sqlalche.me/e/gkpj)
